Workbook
Name Active_Fleet_Actuals: '[1]LTO Board View (Actuals)'!$E$69:$AB$69
Name Asset_Yield_Actuals: '[1]LTO Board View (Actuals)'!$E$181:$AB$181
Name CF_Corp_GA_Actuals: '[1]LTO Board View (Actuals)'!$E$279:$AB$279
Name CF_Corp_SGA_Budget: '[1]LTO Accounting View'!#REF!
Name COGS_Actuals: '[1]LTO Board View (Actuals)'!$E$250:$AB$250
Name Collection_Rate_Actuals: '[1]LTO Board View (Actuals)'!$E$67:$AB$67
Name Cross_Functional_GA_Budget: '[1]LTO Accounting View'!#REF!
Name Cross_Functional_SGA_Actuals: '[1]LTO Board View (Actuals)'!$E$276:$AB$276
Name DA_Actuals: '[1]LTO Board View (Actuals)'!$E$289:$AB$289
Name DA_Budget: '[1]LTO Accounting View'!#REF!
Name Direct_Business_Line_SGA_Budget: '[1]LTO Accounting View'!#REF!
Name Direct_Business_Lines_SGA_Actuals: '[1]LTO Board View (Actuals)'!$E$273:$AB$273
Name Eliminations: #REF!
Name EV_Origination_Actuals: '[1]LTO Board View (Actuals)'!$E$19:$AB$19
Name HEV_Origination_Actuals: '[1]LTO Board View (Actuals)'!$E$18:$AB$18
Name ICE_Origination_Actuals: '[1]LTO Board View (Actuals)'!$E$17:$AB$17
Name Interest_Expense_Actuals: '[1]LTO Board View (Actuals)'!$E$225:$AB$225
Name Interest_Expense_Budget: '[1]LTO Accounting View'!#REF!
Name Interest_Income_Actuals: '[1]LTO Board View (Actuals)'!$E$224:$AB$224
Name Interest_Income_Budget: '[1]LTO Accounting View'!#REF!
Name Inventory_MXNm_Actuals: '[1]LTO Board View (Actuals)'!$E$104:$AB$104
Name Inventory_MXNm_Budget: '[1]LTO Accounting View'!#REF!
Name Inventory_Vehicles_Actuals: '[1]LTO Board View (Actuals)'!$E$89:$AB$89
Name LLR_Actuals: '[1]LTO Board View (Actuals)'!$E$318:$AB$318
Name LLR_PL_Actuals: '[1]LTO Board View (Actuals)'!$E$231:$AB$231
Name LLR_PL_Budget: '[1]LTO Accounting View'!#REF!
Name Maintenance_Budget: '[1]LTO Accounting View'!#REF!
Name ModelS: #REF!
Name Month: Validations!$J$6:$J$16
Name Net_Income_Actuals: '[1]LTO Board View (Actuals)'!$E$296:$AB$296
Name Net_Income_Ex.Corp_Actuals: '[1]LTO Board View (Actuals)'!$E$298:$AB$298
Name Net_Operating_Revenue_Actuals: '[1]LTO Board View (Actuals)'!$E$246:$AB$246
Name Nominal_Interest_Rate_Actuals: '[1]LTO Board View (Actuals)'!$E$172:$AB$172
Name Non_Operating_Rev_Exp_Actuals: '[1]LTO Board View (Actuals)'!$E$284:$AB$284
Name Origination_Actuals: '[1]LTO Board View (Actuals)'!$E$16:$AB$16
Name Other_Operating_Rev.Exp_Budget: '[1]LTO Accounting View'!#REF!
Name Other_Operating_Revenue_Actuals: '[1]LTO Board View (Actuals)'!$E$244:$AB$244
Name Past_Due_Portfolio_Actuals: '[1]LTO Board View (Actuals)'!$E$317:$AB$317
Name Portfolio_Actuals: '[1]LTO Board View (Actuals)'!$E$316:$AB$316
Name Quarters: Validations!$K$6:$K$16
Name Recovered_Vehicles_Actuals: '[1]LTO Board View (Actuals)'!$E$75:$AB$75
Name Recovered_Vehicles_MXNm_Actuals: '[1]LTO Board View (Actuals)'!$E$84:$AB$84
Name Renewal_Rate_Actuals: '[1]LTO Board View (Actuals)'!$E$120:$AB$120
Name Renewals_Actuals: '[1]LTO Board View (Actuals)'!$E$117:$AB$117
Name Selected_Date: '[1]LTO Board View (Actuals)'!$J$2
Name SGA_Actuals: '[1]LTO Board View (Actuals)'!$E$280:$AB$280
Name Shareholders_Equity_Actuals: '[1]LTO Board View (Actuals)'!$E$351:$AB$351
Name Taxes_Actuals: '[1]LTO Board View (Actuals)'!$E$294:$AB$294
Name Taxes_Budget: '[1]LTO Accounting View'!#REF!
Name Terminations_Actuals: '[1]LTO Board View (Actuals)'!$E$118:$AB$118
Name year: Validations!$M$6:$M$7

Sheet Validations
B1: VEMO VCN VALIDATIONS AND CONSISTENCY CHECKS | C1: Check
A2: =+SUM(A3:A1048576) -> #REF! | B2: Managerial Consolidated | C2: =+A2 -> #REF!
J5: Month | K5: Q | M5: Year
J6: ENE | K6: Q1 | M6: 2024
B7: Validations | J7: FEB | K7: Q1 | M7: 2025
J8: MAR | K8: Q1
A9: =+C9 -> #REF! | B9: Total Assets = Total Equity and liabilities (Managerial) | C9: ='Managerial Consolidated'!#REF! -> #REF! | J9: ABR | K9: Q2
A10: =+C10 -> #REF! | B10: Total Assets = Total Equity and liabilities (Board View) | C10: =#REF! -> #REF! | J10: MAY | K10: Q2
A11: =+C11 -> 0 | B11: TB DATA BASE | C11: ='Data BASE'!A1 -> 0 | J11: JUN | K11: Q2
A12: =+C12 -> 0 | B12: Inputs | C12: =Inputs!A55 -> 0 | J12: JUL | K12: Q3
A13: =+C13 -> 0 | B13: Managerial Consolidated | C13: ='Managerial Consolidated'!Q2 -> 0 | J13: AGO | K13: Q3
A14: =+C14 -> #REF! | B14: VCN Board View (Detail) | C14: =#REF! -> #REF! | J14: SEP | K14: Q3
A15: =+C15 -> 0 | B15: Net income from current year P&L = Equity increase in BS | J15: NOV | K15: Q4
A16: =+C16 -> 0 | B16: Cash at the end of period in Cash flow statement = Cash and equivalents in BS | J16: DIC | K16: Q4
B18: Consistency checks
B20: No projections for now

Sheet Cover
AZ4: 2025 YTD
D7: VEMO 2026 Financials
D11: Disclaimer
D12: The material included in this spreadsheet is the property of Mobility Holdco, S.A.P.I. de C.V. (the “Manager”). None of the content in this document is, or should be taken, as a promise or redocument in terms of what may occur in the future. The financial information, including projections and estimates, contained in this document were prepared specifically for its use herein and was based on the best available information at the moment when this model was prepared and shall not be considered as advise or a recommendation for investors or potential investors in terms of investing in any particular transaction or strategy. The Manager makes no redocument or warranty that any projections or estimates herein will be achieved. Any party with access to this document is to rely solely upon its own investigation, evaluation and judgment as to the advisability of investing in the opportunities and strategies as may be described herein. Neither the Manager nor their subsidiaries, associated companies, managers, officers, agents or employees hold any responsibility or liability for verifying any of such projections or estimates. Further, no responsibility of any kind is or will be accepted by the Manager or any of its subsidiaries, associated companies, managers, officers, agents or employees who expressly disclaim any liability which may be based on, or may derive from any information, errors or omissions contained in this document. By its acceptance hereof, each recipient agrees (1) that neither it nor its agents, representatives, directors, officers or employees will copy, reproduce or distribute to others this document, in whole or in part, at any time without the prior written consent of the Manager, and (2) that it will keep permanently confidential all information contained herein and any oral information provided in connection with this document not already in the public domain. Without limiting the foregoing, this document shall be subject to the terms of any separate confidentiality undertaking or agreement entered into by a recipient. The information contained herein has been prepared to assist interested parties in making their own evaluation of the a proposed transaction and does not purport to be all inclusive, nor contain all of the information that a prospective investor may desire should any interested party determine to pursue such particular investment in the future, at which time any interested party would be referred to the definitive regulatory and other legal documents related to any such investment before considering to make any investment decision. There can be no assurance that the targeted returns or results will be met. Actual returns will depend on, among other factors, future operating results, the value of the assets and market conditions at the time of realization. Statements contained in this document that are not historical facts are based on current expectations, estimates, projections, opinions, and beliefs of the Manager. Such statements involve known and unknown risks, uncertainties, and other factors, and undue reliance should not be placed thereon. Additionally, this document contains “forward-looking statements.” Actual events or results or the actual performance of the Trust’s investments may differ materially from those reflected or contemplated in such forward-looking statements. Certain economic and market information contained herein has been obtained from published sources prepared by third parties and in certain cases has not been updated through the date hereof. While such sources are believed to be reliable, the Manager assumes no responsibility for the accuracy or completeness of such information. Neither the Manager, nor their respective affiliates, officers, employees, agents, and consultants make any redocument or warranty as to the accuracy or completeness of the contents of this document and take no responsibility for any loss or damage suffered as a result of any omission, inadequacy, or inaccuracy herein. Recipients acknowledge that circumstances may change and the contents of this document may become outdated as a result.

Sheet Hoja1
A2: Account number | B2: BP Acronym | C2: BP ID | D2: Accronym | E2: Account grouping | F2: Account name | G2: FS | H2: BS Mapping | I2: BS Mapping L-2 | J2: enero | K2: febrero | L2: final | O2: Pague | P2: Aumento
A3: 105-01-001 | B3: [MC] | C3: [MC] | 105-01-001 | D3: [VCN] | E3: Cuentas por cobrar | F3: CONEKTA | G3: BS | H3: Assets | I3: Other Accounts Receivable | J3: 156206.38 | K3: 6890.84 | L3: =-(K3-J3) -> 149315.54 | N3: Cuentas por cobrar | O3: =L3+L12 -> 1470691.3 | P3: =L5 -> -165565.64 | R3: 1470691.3 | S3: -165565.64
A4: 105-01-002 | B4: [MC] | C4: [MC] | 105-01-002 | D4: [VCN] | E4: Cuentas por cobrar | F4: MULTISERVICIOS NACIONALES MODELO | G4: BS | H4: Assets | I4: Other Accounts Receivable | J4: 0 | K4: 0 | L4: =K4-J4 -> 0
A5: 105-01-003 | B5: [MC] | C5: [MC] | 105-01-003 | D5: [VCN] | E5: Cuentas por cobrar | F5: PUNTO A PUNTO T2 | G5: BS | H5: Assets | I5: Other Accounts Receivable | J5: 1255093.7 | K5: 1420659.3 | L5: =-(K5-J5) -> -165565.64 | N5: Cuentas por cobrar partes relacionadas | O5: 0 | P5: =L13+L14 -> -3491489.9 | S5: -3491490
A6: 105-01-005 | B6: [MC] | C6: [MC] | 105-01-005 | D6: [VCN] | E6: Cuentas por cobrar | F6: ENGIE MEX CONSULTORES | G6: BS | H6: Assets | I6: Other Accounts Receivable | J6: 370.6 | K6: 370.6 | L6: =K6-J6 -> 0
A7: 105-01-006 | B7: [MC] | C7: [MC] | 105-01-006 | D7: [VCN] | E7: Cuentas por cobrar | F7: FORD MOTORS COMPANY | G7: BS | H7: Assets | I7: Other Accounts Receivable | J7: 43.43 | K7: 43.43 | L7: =K7-J7 -> 0
A8: 105-01-007 | B8: [MC] | C8: [MC] | 105-01-007 | D8: [VCN] | E8: Cuentas por cobrar | F8: HARD SISTEMAS DE VANGUARDIA | G8: BS | H8: Assets | I8: Other Accounts Receivable | J8: 80.35 | K8: 80.35 | L8: =K8-J8 -> 0
A9: 105-01-008 | B9: [MC] | C9: [MC] | 105-01-008 | D9: [VCN] | E9: Cuentas por cobrar | F9: BIOMEDICS | G9: BS | H9: Assets | I9: Other Accounts Receivable | J9: 376.76 | K9: 376.76 | L9: =K9-J9 -> 0
A10: 105-01-009 | B10: [MC] | C10: [MC] | 105-01-009 | D10: [VCN] | E10: Cuentas por cobrar | F10: CONSULTORES EN EFECTIVIDAD GERENCIAL | G10: BS | H10: Assets | I10: Other Accounts Receivable | J10: 85.23 | K10: 85.23 | L10: =K10-J10 -> 0
A11: 105-01-010 | B11: [MC] | C11: [MC] | 105-01-010 | D11: [VCN] | E11: Cuentas por cobrar | F11: CERVEZAS CUAUHTEMOC MOCTEZUMA | G11: BS | H11: Assets | I11: Other Accounts Receivable | J11: 0 | K11: 0 | L11: =K11-J11 -> 0
A12: 105-01-011 | B12: [MC] | C12: [MC] | 105-01-011 | D12: [VCN] | E12: Cuentas por cobrar | F12: DAIMLER VEHICULOS COMERCIALES MEXICO | G12: BS | H12: Assets | I12: Other Accounts Receivable | J12: 5857369.4 | K12: 4535993.7 | L12: =-(K12-J12) -> 1321375.7 | N12: Pagos anticipados | O12: =L17 -> 2645.83 | P12: =L16 -> -35127.38 | R12: 2645.83 | S12: -35127.38
A13: 106-03-001 | B13: [MC] | C13: [MC] | 106-03-001 | D13: [VCN] | E13: Cuentas por cobrar partes relacionadas | F13: Mobility DAE SA de CV | G13: BS | H13: Assets | I13: Intercompany Accounts Receivable | J13: 34025682 | K13: 37423900 | L13: =-(K13-J13) -> -3398218.2 | N13: Activo por derecho de uso | O13: 0 | P13: =L20 -> 634311 | S13: -634311
A14: 106-03-003 | B14: [MC] | C14: [MC] | 106-03-003 | D14: [VCN] | E14: Cuentas por cobrar partes relacionadas | F14: Vemo Comercial Fleets SA de CV | G14: BS | H14: Assets | I14: Intercompany Accounts Receivable | J14: 1156470.5 | K14: 1249742.2 | L14: =-(K14-J14) -> -93271.73 | N14: Provisiones | O14: =L30 -> -5937.6 | P14: =L29+L31 -> 297276.85 | R14: 5937.6 | S14: -297276.85
A15: 106-03-005 | B15: [MC] | C15: [MC] | 106-03-005 | D15: [VCN] | E15: Cuentas por cobrar partes relacionadas | F15: Au Haus Ingenieria | G15: BS | H15: Assets | I15: Intercompany Accounts Receivable | J15: 0 | K15: 0 | L15: =-(K15-J15) -> 0
A16: 109-01-001 | B16: [MC] | C16: [MC] | 109-01-001 | D16: [VCN] | E16: Pagos anticipados | F16: Nacional Provincial SAB | G16: BS | H16: Assets | I16: Payments In Advance | J16: 38203.47 | K16: 73330.85 | L16: =-(K16-J16) -> -35127.38 | N16: Pasivos por arrendamiento | O16: =L32+L34+L35+L36+L37 -> -497731.19 | P16: =L33 -> 62861.98 | R16: 497731.19 | S16: -62861.98
A17: 109-01-002 | B17: [MC] | C17: [MC] | 109-01-002 | D17: [VCN] | E17: Pagos anticipados | F17: Aseguradora Aserta | G17: BS | H17: Assets | I17: Payments In Advance | J17: 5291.67 | K17: 2645.84 | L17: =-(K17-J17) -> 2645.83 | N17: Cuentas por pagar partes relacionadas | O17: =L40 -> -4135236.2 | P17: =L41+L43+L46 -> 199343.14 | R17: 4135236.2 | S17: -199343.14
A18: 120-05-000 | B18: [MC] | C18: [MC] | 120-05-000 | D18: [VCN] | E18: Anticipo a proveedores | F18: AT T COMUNICACIONES DIGITALES S DE RL DE CV | G18: BS | H18: Assets | I18: Payments In Advance | J18: 0 | K18: 0 | L18: =-(K18-J18) -> 0
A19: 161-01-000 | B19: [MC] | C19: [MC] | 161-01-000 | D19: [VCN] | E19: Activo por derecho de uso | F19: Activo por derecho de uso | G19: BS | H19: Assets | I19: Lease Asset (NIF D5) | J19: 71455175 | K19: 71455175 | L19: =-(K19-J19) -> 0
A20: 171-19-000 | B20: [MC] | C20: [MC] | 171-19-000 | D20: [VCN] | E20: Activo por derecho de uso | F20: Depreciacion por activo de uso | G20: BS | H20: Assets | I20: Lease Asset (NIF D5) | J20: -8162249.1 | K20: -8796560.1 | L20: =-(K20-J20) -> 634311 | P20: =L39 -> -610000 | S20: -610000
A21: 184-01-001 | B21: [MC] | C21: [MC] | 184-01-001 | D21: [VCN] | E21: Otras cuentas por cobrar y activos circulantes | F21: COMISION FEDERAL DE ELECTRICIDAD | G21: BS | H21: Assets | I21: Other Accounts Receivable | J21: 776459 | K21: 776459 | L21: =-(K21-J21) -> 0
A22: 184-02-001 | B22: [MC] | C22: [MC] | 184-02-001 | D22: [VCN] | E22: Otras cuentas por cobrar y activos circulantes | F22: Montag Escenografia SA de CV | G22: BS | H22: Assets | I22: Other Accounts Receivable | J22: 341504 | K22: 341504 | L22: =-(K22-J22) -> 0
A23: 184-02-002 | B23: [MC] | C23: [MC] | 184-02-002 | D23: [VCN] | E23: Otras cuentas por cobrar y activos circulantes | F23: Inmobiliaria Conjunto Polanco SAPI de CV | G23: BS | H23: Assets | I23: Other Accounts Receivable | J23: 137592 | K23: 137592 | L23: =-(K23-J23) -> 0
A24: 184-02-003 | B24: [MC] | C24: [MC] | 184-02-003 | D24: [VCN] | E24: Otras cuentas por cobrar y activos circulantes | F24: Estacionamienti Boyen SA de CV | G24: BS | H24: Assets | I24: Other Accounts Receivable | J24: 840000 | K24: 840000 | L24: =-(K24-J24) -> 0
A25: 184-02-004 | B25: [MC] | C25: [MC] | 184-02-004 | D25: [VCN] | E25: Otras cuentas por cobrar y activos circulantes | F25: TRANSACTIONAL BANKING MEXICO | G25: BS | H25: Assets | I25: Other Accounts Receivable | J25: 440203.72 | K25: 440203.72 | L25: =-(K25-J25) -> 0
A26: 184-02-005 | B26: [MC] | C26: [MC] | 184-02-005 | D26: [VCN] | E26: Otras cuentas por cobrar y activos circulantes | F26: FIDEICOMISO FIBRA UNO | G26: BS | H26: Assets | I26: Other Accounts Receivable | J26: 297310 | K26: 297310 | L26: =-(K26-J26) -> 0
A27: 184-02-006 | B27: [MC] | C27: [MC] | 184-02-006 | D27: [VCN] | E27: Otras cuentas por cobrar y activos circulantes | F27: FIDEICOMISO ALEPH | G27: BS | H27: Assets | I27: Other Accounts Receivable | J27: 16456.82 | K27: 16456.82 | L27: =-(K27-J27) -> 0
A28: 210-01-000 | B28: [MC] | C28: [MC] | 210-01-000 | D28: [VCN] | E28: Provisiones | F28: Provisión de sueldos y salarios x pagar | G28: BS | H28: Liabilities | I28: Provisions for Miscellaneous Obligations (portfolio and non-portfolio related) | J28: 0 | K28: 0 | L28: =-(K28-J28) -> 0
A29: 210-03-000 | B29: [MC] | C29: [MC] | 210-03-000 | D29: [VCN] | E29: Provisiones | F29: Provisión de aguinaldo por pagar | G29: BS | H29: Liabilities | I29: Provisions for Miscellaneous Obligations (portfolio and non-portfolio related) | J29: -22841.7 | K29: -37176.55 | L29: =-(K29-J29) -> 14334.85 | R29: =SUM(R3:R20) -> 6112242 | S29: =SUM(S3:S20) -> -5495975.9
A30: 210-08-000 | B30: [MC] | C30: [MC] | 210-08-000 | D30: [VCN] | E30: Provisiones | F30: Provisión prima vacaional | G30: BS | H30: Liabilities | I30: Provisions for Miscellaneous Obligations (portfolio and non-portfolio related) | J30: -25333.32 | K30: -19395.72 | L30: =-(K30-J30) -> -5937.6 | S30: =S29+R29 -> 616266.11
A31: 210-09-000 | B31: [MC] | C31: [MC] | 210-09-000 | D31: [VCN] | E31: Provisiones | F31: Provisión Bono | G31: BS | H31: Liabilities | I31: Provisions for Miscellaneous Obligations (portfolio and non-portfolio related) | J31: -5855759.6 | K31: -6138701.6 | L31: =-(K31-J31) -> 282942
A32: 218-02-001 | B32: [MC] | C32: [MC] | 218-02-001 | D32: [VCN] | E32: Pasivos por arrendamiento | F32: Fideicomiso aleph, banco ve por mas, fid 42 | G32: BS | H32: Liabilities | I32: Lease Liabilities (NIF D5) | J32: -3018998.9 | K32: -2860206.1 | L32: =-(K32-J32) -> -158792.84
A33: 218-02-002 | B33: [MC] | C33: [MC] | 218-02-002 | D33: [VCN] | E33: Pasivos por arrendamiento | F33: Cibanco SA CIB/477 | G33: BS | H33: Liabilities | I33: Lease Liabilities (NIF D5) | J33: -2684197.3 | K33: -2747059.2 | L33: =-(K33-J33) -> 62861.98
A34: 218-02-003 | B34: [MC] | C34: [MC] | 218-02-003 | D34: [VCN] | E34: Pasivos por arrendamiento | F34: Inmobiliaria conjunto polanco | G34: BS | H34: Liabilities | I34: Lease Liabilities (NIF D5) | J34: -1380493.6 | K34: -1347422.6 | L34: =-(K34-J34) -> -33071
A35: 218-02-004 | B35: [MC] | C35: [MC] | 218-02-004 | D35: [VCN] | E35: Pasivos por arrendamiento | F35: Fibra HD (Lomas Verdes) | G35: BS | H35: Liabilities | I35: Lease Liabilities (NIF D5) | J35: -272307.28 | K35: -249528.07 | L35: =-(K35-J35) -> -22779.21
A36: 218-02-005 | B36: [MC] | C36: [MC] | 218-02-005 | D36: [VCN] | E36: Pasivos por arrendamiento | F36: Desarrolladora de Estacionamientos (Monumento) | G36: BS | H36: Liabilities | I36: Lease Liabilities (NIF D5) | J36: -1582575.3 | K36: -1391703.8 | L36: =-(K36-J36) -> -190871.5
A37: 218-02-006 | B37: [MC] | C37: [MC] | 218-02-006 | D37: [VCN] | E37: Pasivos por arrendamiento | F37: Fideicomiso Fibra UNO (Torre Mexicana) | G37: BS | H37: Liabilities | I37: Lease Liabilities (NIF D5) | J37: -1055992.3 | K37: -963775.65 | L37: =-(K37-J37) -> -92216.64
A38: 256-02-000 | B38: [MC] | C38: [MC] | 256-02-000 | D38: [VCN] | E38: Pasivos por arrendamiento | F38: Pasivo por arrendamiento | G38: BS | H38: Liabilities | I38: Lease Liabilities (NIF D5) | J38: -55990068 | K38: -55990068 | L38: =-(K38-J38) -> 0
A39: 109-23-001 | B39: [MC] | C39: [MC] | 109-23-001 | D39: [VCN] | E39: Pagos anticipados | F39: BAJA MAR DE CORTES SA DE CV | G39: BS | H39: Assets | I39: Payments In Advance | J39: 0 | K39: 610000 | L39: =-(K39-J39) -> -610000
A40: 219-01-001 | B40: [MC] | C40: =+B40&" | "&A40 -> [MC] | 219-01-001 | D40: [VCN] | E40: Cuentas por pagar partes relacionadas | F40: Prestadora de Servicios de Mobilidad SA DE CV | G40: BS | H40: Liabilities | I40: Accounts Payable (Related Parties) | J40: -4135236.2 | K40: 0 | L40: =-(K40-J40) -> -4135236.2
A41: 219-01-002 | B41: [MC] | C41: =+B41&" | "&A41 -> [MC] | 219-01-002 | D41: [VCN] | E41: Cuentas por pagar partes relacionadas | F41: FINANCIERA POR EL IMPULSO ECONOMICO SA DE CV SOFOM | G41: BS | H41: Liabilities | I41: Accounts Payable (Related Parties) | J41: -2606570 | K41: -2610769 | L41: =-(K41-J41) -> 4199
...

Sheet Scenarios
C1: VEMO VCN 2026 Financials
C2: Scenarios VCN
B4: x | D4: UNITS | E4: COMMENT | F4: ASSUMPTION | AZ4: 2025 YTD
Z5: 46053
Z6: 46081
E7: Select Month | F7: 46142 | I7: BP | J7: ACC | Z7: 46112
E8: Select Case | F8: 1 | I8: 1 | J8: 2 | Z8: 46142
F9: {=INDEX(I9:K9,,F$8)} -> Board View | I9: Board View | J9: Acc | Z9: 46173
Z10: 46203
Z11: 46234
C12: View | Z12: 46265
Z13: 46295
C14: BP/ Acc | Z14: 46326
D15: View | E15: [DATA] | F15: {=INDEX(I15:K15,,F$8)} -> BP | I15: BP | J15: ACC | Z15: 46356
Z16: 46387

Sheet Data BASE
A1: =SUM(A578:A921) -> 0 | B1: Vemo Data | Q1: check P&L | R1: =+SUMIF($H$490:$H$6026,"P&L",R$12:R$443) -> 5005846.5 | S1: =+SUMIF($H$490:$H$6026,"P&L",S$12:S$443) -> 11529539 | T1: =+SUMIF($H$490:$H$6026,"P&L",T$12:T$443) -> 17937902 | U1: =+SUMIF($H$490:$H$6026,"P&L",U$12:U$443) -> 24264030 | V1: =+SUMIF($H$490:$H$6026,"P&L",V$12:V$443) -> 29062722 | W1: =+SUMIF($H$490:$H$6026,"P&L",W$12:W$443) -> 35139553 | X1: =+SUMIF($H$490:$H$6026,"P&L",X$12:X$443) -> 43045509 | Y1: =+SUMIF($H$490:$H$6026,"P&L",Y$12:Y$443) -> 49597661 | ... AO1: =+SUMIF($H$490:$H$6026,"P&L",AO$12:AO$443) -> 0
B2: VCN Business Plan View (Detail) | Q2: Check BS | R2: =SUM(R13:R487) -> 1.0739313e-08 | S2: =SUM(S13:S487) -> 2.2526365e-08 | T2: =SUM(T13:T487) -> 0.011936519 | U2: =SUM(U13:U487) -> -7.1944669e-08 | V2: =SUM(V13:V487) -> 1.2852252e-07 | W2: =SUM(W13:W487) -> -9.4762072e-08 | X2: =SUM(X13:X487) -> -5.6577846e-08 | Y2: =SUM(Y13:Y487) -> 4.8195943e-08 | ... AG2: =SUM(AG13:AG487) -> 1.2398232e-07 | AH2: =SUM(AH13:AH443) -> 0 | AI2: =SUM(AI13:AI443) -> 0 | AJ2: =SUM(AJ13:AJ443) -> 0 | AK2: =SUM(AK13:AK443) -> 0 | AL2: =SUM(AL13:AL443) -> 0 | AM2: =SUM(AM13:AM443) -> 0 | AN2: =SUM(AN13:AN443) -> 0 | AO2: =SUM(AO13:AO443) -> 0 | AP2: 813074.55
AP3: 2483918.6
AP4: -670251.99
AP5: -631296
B6: Month Start | R6: 45658 | S6: 45689 | T6: 45717 | U6: 45748 | V6: 45778 | W6: 45809 | X6: 45839 | Y6: 45870 | Z6: 45901 | AA6: 45931 | AB6: 45962 | AC6: 45992 | AD6: 46023 | AE6: 46054 | AF6: 46082 | AG6: 46113 | AH6: 46143 | AI6: 46174 | AJ6: 46204 | AK6: 46235 | AL6: 46266 | AM6: 46296 | AN6: 46327 | AO6: 46357
B7: Month End | R7: 45688 | S7: 45716 | T7: 45747 | U7: 45777 | V7: 45808 | W7: 45838 | X7: 45869 | Y7: 45900 | Z7: 45930 | AA7: 45961 | AB7: 45991 | AC7: 46022 | AD7: 46053 | AE7: 46081 | AF7: 46112 | AG7: 46142 | AH7: 46173 | AI7: 46203 | AJ7: 46234 | AK7: 46265 | AL7: 46295 | AM7: 46326 | AN7: 46356 | AO7: 46387
B8: Year | R8: 2025 | S8: 2025 | T8: 2025 | U8: 2025 | V8: 2025 | W8: 2025 | X8: 2025 | Y8: 2025 | Z8: 2025 | AA8: 2025 | AB8: 2025 | AC8: 2025 | AD8: 2026 | AE8: 2026 | AF8: 2026 | AG8: 2026 | AH8: 2026 | AI8: 2026 | AJ8: 2026 | AK8: 2026 | AL8: 2026 | AM8: 2026 | AN8: 2026 | AO8: 2026
B9: Quarter | R9: Q1 | S9: Q1 | T9: Q1 | U9: Q2 | V9: Q2 | W9: Q2 | X9: Q3 | Y9: Q3 | Z9: Q3 | AA9: Q4 | AB9: Q4 | AC9: Q4 | AD9: Q1 | AE9: Q1 | AF9: Q1 | AG9: Q2 | AH9: Q2 | AI9: Q2 | AJ9: Q3 | AK9: Q3 | AL9: Q3 | AM9: Q4 | AN9: Q4 | AO9: Q4
B10: Actuals | R10: Actuals | S10: Actuals | T10: Actuals | U10: Actuals | V10: Actuals | W10: Actuals | X10: Actuals | Y10: Actuals | Z10: Actuals | AA10: Actuals | AB10: Actuals | AC10: Actuals | AD10: Actuals | AE10: Actuals | AF10: Actuals | AG10: Actuals
B12: Account number | C12: BP Acronym | D12: BP ID | E12: Accronym | F12: Account grouping | G12: Account name | H12: FS | I12: BS Mapping | J12: BS Mapping L-2 | K12: FS Budget (Board) | L12: FS Budget (Board) L-2 | M12: FS Budget (Board) L-3 | N12: FS Budget (Board) L-4 | O12: SG&A Consolidated | Q12: Consolidated | R12: 45658 | S12: 45689 | T12: 45717 | U12: 45748 | V12: 45778 | W12: 45809 | X12: 45839 | Y12: 45870 | Z12: 45901 | AA12: 45931 | AB12: 45962 | AC12: 45992 | AD12: 46023 | AE12: 46054 | AF12: 46082 | AG12: 46113 | AH12: 46143 | AI12: 46174 | AJ12: 46204 | AK12: 46235 | AL12: 46266 | AM12: 46296 | AN12: 46327 | AO12: 46357
B13: 100-100-100-2122 | C13: [VCN] | D13: [VCN]100-100-100-2122 | E13: [VCN] | F13: Efectivo y equivalentes de efectivo | G13: BBVA MXN 0117966253 (CHARGING) | H13: BS | I13: Assets | J13: Cash & Eq. | K13: n.a. | L13: n.a. | M13: n.a. | N13: n.a. | O13: n.a. | P13: n.a. | Q13: Combinado | R13: 20031.38 | S13: 21420.23 | T13: 22234.02 | U13: 26807.43 | V13: 66331.13 | W13: 22588.75 | X13: 23381.08 | Y13: 27964.86 | Z13: 20825.67 | AA13: 23424.05 | AB13: 28191.62 | AC13: 22993.18 | AD13: 22017.25 | AE13: 22615.11 | AF13: 20949.5 | AG13: 25559.23
B14: 100-100-100-2123 | C14: [VCN] | D14: [VCN]100-100-100-2123 | E14: [VCN] | F14: Efectivo y equivalentes de efectivo | G14: BBVA MXN 0118149518 (CHARGING) | H14: BS | I14: Assets | J14: Cash & Eq. | K14: n.a. | L14: n.a. | M14: n.a. | N14: n.a. | O14: n.a. | P14: n.a. | Q14: Combinado | R14: 526087.72 | S14: 293884.71 | T14: 508032.1 | U14: 34605.57 | V14: 59376.68 | W14: 41538.44 | X14: 12757941 | Y14: 228982.2 | Z14: 2564835.9 | AA14: 439539.16 | AB14: 37090.51 | AC14: 14635515 | AD14: 597273.38 | AE14: 461002.64 | AF14: 1468592.5 | AG14: 8637.42
B15: 102-01-003 | C15: [VCN] | D15: [VCN]102-01-003 | E15: [VCN] | F15: Efectivo y equivalentes de efectivo | G15: BBVA 0119831797 | H15: BS | I15: Assets | J15: Cash & Eq. | K15: n.a. | L15: n.a. | M15: n.a. | N15: n.a. | O15: n.a. | P15: n.a. | Q15: Combinado | R15: 0 | S15: 0 | T15: 0 | U15: 0 | V15: 0 | W15: 0 | X15: 0 | Y15: 0 | Z15: 0 | AA15: 0 | AB15: 0 | AC15: 0 | AD15: 0 | AE15: 0 | AF15: 0 | AG15: 0
B16: 103-01-001 | C16: [VCN] | D16: [VCN]103-01-001 | E16: [VCN] | F16: Efectivo y equivalentes de efectivo | G16: INVERSIONES BASE | H16: BS | I16: Assets | J16: Cash & Eq. | K16: n.a. | L16: n.a. | M16: n.a. | N16: n.a. | O16: n.a. | P16: n.a. | Q16: Combinado | R16: 1300000 | S16: 0.04 | T16: 1201013.8 | U16: 100023.24 | V16: 270079.01 | W16: 250207.34 | X16: 0 | Y16: 0 | Z16: 0 | AA16: 0 | AB16: 0 | AC16: 0 | AD16: 0 | AE16: 0 | AF16: 0 | AG16: 0
B17: 105-01-001 | C17: [VCN] | D17: [VCN]105-01-001 | E17: [VCN] | F17: Cuentas por cobrar comerciales | G17: CONEKTA | H17: BS | I17: Assets | J17: Other Accounts Receivable | K17: n.a. | L17: n.a. | M17: n.a. | N17: n.a. | O17: n.a. | P17: n.a. | Q17: Combinado | R17: 1541.37 | S17: -66111.16 | T17: -1132238.6 | U17: 0 | V17: 0 | W17: 0 | X17: 0 | Y17: 0 | Z17: 0 | AA17: 0 | AB17: 0 | AC17: 0 | AD17: 0 | AE17: 0 | AF17: 0 | AG17: 0
B18: 100-100-100-4001 | C18: [VCN] | D18: [VCN]100-100-100-4001 | E18: [VCN] | F18: Cuentas por cobrar comerciales | G18: CLIENTES NACIONALES | H18: BS | I18: Assets | J18: Other Accounts Receivable | K18: n.a. | L18: n.a. | M18: n.a. | N18: n.a. | O18: n.a. | P18: n.a. | Q18: Combinado | R18: 5623755.8 | S18: 5625363.1 | T18: 5623755.8 | U18: 5794985.8 | V18: 7100654.5 | W18: 6244661.6 | X18: 6426751.9 | Y18: 6106871.4 | Z18: 2292333.2 | AA18: 3139705.2 | AB18: 2099648 | AC18: 2459413 | AD18: 2608893.2 | AE18: 5717142.5 | AF18: 5916840.8 | AG18: 3586543.2
B19: 105-01-005 | C19: [VCN] | D19: [VCN]105-01-005 | E19: [VCN] | F19: Cuentas por cobrar comerciales | G19: ENGIE MEX CONSULTORES | H19: BS | I19: Assets | J19: Other Accounts Receivable | K19: n.a. | L19: n.a. | M19: n.a. | N19: n.a. | O19: n.a. | P19: n.a. | Q19: Combinado | R19: 0 | S19: 0 | T19: 0 | U19: 0 | V19: 0 | W19: 0 | X19: 0 | Y19: 0 | Z19: 0 | AA19: 0 | AB19: 0 | AC19: 0 | AD19: 0 | AE19: 0 | AF19: 0 | AG19: 0
B20: 105-01-006 | C20: [VCN] | D20: [VCN]105-01-006 | E20: [VCN] | F20: Cuentas por cobrar comerciales | G20: FORD MOTORS COMPANY | H20: BS | I20: Assets | J20: Other Accounts Receivable | K20: n.a. | L20: n.a. | M20: n.a. | N20: n.a. | O20: n.a. | P20: n.a. | Q20: Combinado | R20: 0 | S20: 0 | T20: 0 | U20: 0 | V20: 0 | W20: 0 | X20: 0 | Y20: 0 | Z20: 0 | AA20: 0 | AB20: 0 | AC20: 0 | AD20: 0 | AE20: 0 | AF20: 0 | AG20: 0
B21: 105-01-007 | C21: [VCN] | D21: [VCN]105-01-007 | E21: [VCN] | F21: Cuentas por cobrar comerciales | G21: HARD SISTEMAS DE VANGUARDIA | H21: BS | I21: Assets | J21: Other Accounts Receivable | K21: n.a. | L21: n.a. | M21: n.a. | N21: n.a. | O21: n.a. | P21: n.a. | Q21: Combinado | R21: 0 | S21: 0 | T21: 0 | U21: 0 | V21: 0 | W21: 0 | X21: 0 | Y21: 0 | Z21: 0 | AA21: 0 | AB21: 0 | AC21: 0 | AD21: 0 | AE21: 0 | AF21: 0 | AG21: 0
B22: 105-01-008 | C22: [VCN] | D22: [VCN]105-01-008 | E22: [VCN] | F22: Cuentas por cobrar comerciales | G22: BIOMEDICS | H22: BS | I22: Assets | J22: Other Accounts Receivable | K22: n.a. | L22: n.a. | M22: n.a. | N22: n.a. | O22: n.a. | P22: n.a. | Q22: Combinado | R22: 0 | S22: 0 | T22: 0 | U22: 0 | V22: 0 | W22: 0 | X22: 0 | Y22: 0 | Z22: 0 | AA22: 0 | AB22: 0 | AC22: 0 | AD22: 0 | AE22: 0 | AF22: 0 | AG22: 0
B23: 105-01-009 | C23: [VCN] | D23: [VCN]105-01-009 | E23: [VCN] | F23: Cuentas por cobrar comerciales | G23: CONSULTORES EN EFECTIVIDAD GERENCIAL | H23: BS | I23: Assets | J23: Other Accounts Receivable | K23: n.a. | L23: n.a. | M23: n.a. | N23: n.a. | O23: n.a. | P23: n.a. | Q23: Combinado | R23: 0 | S23: 0 | T23: 0 | U23: 0 | V23: 0 | W23: 0 | X23: 0 | Y23: 0 | Z23: 0 | AA23: 0 | AB23: 0 | AC23: 0 | AD23: 0 | AE23: 0 | AF23: 0 | AG23: 0
B24: 105-01-011 | C24: [VCN] | D24: [VCN]105-01-011 | E24: [VCN] | F24: Cuentas por cobrar comerciales | G24: DAIMLER VEHICULOS COMERCIALES MEXICO | H24: BS | I24: Assets | J24: Other Accounts Receivable | K24: n.a. | L24: n.a. | M24: n.a. | N24: n.a. | O24: n.a. | P24: n.a. | Q24: Combinado | R24: 692427.19 | S24: 692427.19 | T24: 692427.19 | U24: 692427.19 | V24: -0.01 | W24: 0 | X24: 0 | Y24: 0 | Z24: 0 | AA24: 0 | AB24: 0 | AC24: 0 | AD24: 0 | AE24: 0 | AF24: 0 | AG24: 0
... B303: 600-700-000-9009 | C303: [VCN] | D303: [VCN]600-700-000-9009 | E303: [VCN] | F303: Depreciación de mobiliario y equipo | G303: DEPRECIACION MODULOS DE POTENCIA | H303: P&L | I303: Equity | J303: Retained earnings (Current Year) | K303: D&A | L303: D&A | M303: Charging Infra D&A | N303: Charging Infra D&A | O303: D&A | P303: D&A | Q303: Combinado | R303: 0 | S303: 0 | T303: 0 | U303: 60694.47 | V303: 121388.94 | W303: 121388.94 | X303: 0 | Y303: 0 | Z303: 41222.08 | AA303: 82444.16 | AB303: 129698.74 | AC303: 183991.24 | AD303: 56303.34 | AE303: 112606.68 | AF303: 168910.02 | AG303: 225213.02
B304: x | C304: [VCN] | D304: [VCN]x | E304: [VCN] | F304: Ingresos operativos | G304: Ingresos estación de carga | H304: P&L | I304: Equity | J304: Retained earnings (Current Year) | K304: Revenue | L304: Activation Revenue | M304: LTO Additional Consumption | N304: LTO Additional Consumption | O304: Revenue | P304: Revenue | Q304: Combinado | R304: 0 | S304: 0 | T304: 0 | V304: 0 | W304: 0 | X304: 0 | Y304: 0 | Z304: 0 | AA304: 0 | AB304: 0 | AC304: 0 | AD304: 0 | AE304: 0 | AF304: 0 | AG304: 0
B305: 602-52-012 | C305: [VCN] | D305: [VCN]602-52-012 | E305: [VCN] | F305: Gastos generales | G305: Puerta Polanco 2 | H305: P&L | I305: Equity | J305: Retained earnings (Current Year) | K305: OPEX | L305: Non Operating Expense | M305: Energy LV | N305: Charging Infra | O305: OPEX | P305: SG&A | Q305: Combinado | R305: 0 | S305: 0 | T305: 0 | U305: 0 | V305: 0 | W305: 0 | X305: 0 | Y305: 0 | Z305: 0 | AA305: 0 | AB305: 0 | AC305: 0 | AD305: 0 | AE305: 0 | AF305: 0 | AG305: 0
B306: 602-46-012 | C306: [VCN] | D306: [VCN]602-46-012 | E306: [VCN] | F306: Gastos generales | G306: Torre Mexicana | H306: P&L | I306: Equity | J306: Retained earnings (Current Year) | K306: OPEX | L306: Non Operating Expense | M306: Rent TM | N306: Charging Infra | O306: OPEX | P306: SG&A | Q306: Combinado | R306: 0 | S306: 0 | T306: 0 | U306: 0 | V306: 0 | W306: 0 | X306: 0 | Y306: 0 | Z306: 0 | AA306: 0 | AB306: 0 | AC306: 0 | AD306: 0 | AE306: 0 | AF306: 0 | AG306: 0
B307: 105-01-022 | C307: [VCN] | D307: [VCN]105-01-022 | E307: [VCN] | F307: Cuentas por cobrar comerciales | G307: VIZEON NUEVA ENERGIA | H307: BS | I307: Assets | J307: Other Accounts Receivable | K307: n.a. | L307: n.a. | M307: n.a. | N307: n.a. | O307: n.a. | Q307: Combinado | R307: 0 | S307: 0 | T307: 0 | U307: 0 | V307: 1192.48 | W307: 1192.48 | X307: 1192.48 | Y307: 1192.48 | Z307: 0 | AA307: 0 | AB307: 596.54 | AC307: 1261.64 | AD307: 1261.64 | AE307: 456 | AF307: 0 | AG307: 0
B308: 109-23-002 | C308: [VCN] | D308: [VCN]109-23-002 | E308: [VCN] | F308: Pagos anticipados | G308: FIDEICOMISO IRREVOCABLE 5813 | H308: BS | I308: Assets | J308: Payments In Advance | K308: n.a. | L308: n.a. | M308: n.a. | N308: n.a. | O308: n.a. | Q308: Combinado | R308: 0 | S308: 0 | T308: 0 | U308: 0 | V308: 400000 | W308: 0 | X308: 0 | Y308: 0 | Z308: 0 | AA308: 0 | AB308: 0 | AC308: 0 | AD308: 0 | AE308: 0 | AF308: 0 | AG308: 0
B309: 120-01-014 | C309: [VCN] | D309: [VCN]120-01-014 | E309: [VCN] | F309: Anticipo a proveedores | G309: RAUL IGNACIO TERROBA Y WOLFF | H309: BS | I309: Assets | J309: Payments In Advance | K309: n.a. | L309: n.a. | M309: n.a. | N309: n.a. | O309: n.a. | Q309: Combinado | R309: 0 | S309: 0 | T309: 0 | U309: 0 | V309: 428750 | W309: 428750 | X309: 428750 | Y309: 428750 | Z309: 428750 | AA309: 428750 | AB309: 428750 | AC309: 0 | AD309: 707437.5 | AE309: 986125 | AF309: 0 | AG309: 0
B310: 120-01-015 | C310: [VCN] | D310: [VCN]120-01-015 | E310: [VCN] | F310: Anticipo a proveedores | G310: GOOGLE OPERACIONES DE MEXICO | H310: BS | I310: Assets | J310: Payments In Advance | K310: n.a. | L310: n.a. | M310: n.a. | N310: n.a. | O310: n.a. | Q310: Combinado | R310: 0 | S310: 0 | T310: 0 | U310: 0 | V310: 82360 | W310: 0 | X310: 17400 | Y310: 17400 | Z310: 17400 | AA310: 0 | AB310: 0 | AC310: 0 | AD310: 0 | AE310: 0 | AF310: 0 | AG310: 0
B311: 120-03-001 | C311: [VCN] | D311: [VCN]120-03-001 | E311: [VCN] | F311: Cuentas por cobrar partes relacionadas | G311: VEMO COMERCIAL FLEETS | H311: BS | I311: Assets | J311: Intercompany Accounts Receivable | K311: n.a. | L311: n.a. | M311: n.a. | N311: n.a. | O311: n.a. | Q311: Combinado | R311: 0 | S311: 0 | T311: 0 | U311: 0 | V311: 192385.12 | W311: 163577.68 | X311: 134770.24 | Y311: 105962.8 | Z311: 77155.36 | AA311: 48347.92 | AB311: 19540.48 | AC311: 0 | AD311: 0 | AE311: 0 | AF311: 0 | AG311: 0
B312: 701-12-000 | C312: [VCN] | D312: [VCN]701-12-000 | E312: [VCN] | F312: Intereses a cargo | G312: Intereses a cargo por Obligaciones Convertibles | H312: P&L | I312: Equity | J312: Retained earnings (Current Year) | K312: Direct Business Lines SG&A | L312: Interest expense | M312: Interest expense | N312: Interest expense | O312: SG&A | P312: Interest Expense | Q312: Combinado | R312: 0 | S312: 0 | T312: 0 | U312: 0 | V312: 1577778 | W312: 2911111 | X312: 4244444 | Y312: 5577777 | Z312: 6205290 | AA312: 7552232 | AB312: 8882426 | AC312: 0 | AD312: 1259244 | AE312: 2510372 | AF312: 0 | AG312: 0
B313: 501-09-000 | C313: [VCN] | D313: [VCN]501-09-000 | E313: [VCN] | F313: Costos de ventas | G313: Cargadores e Instalacion | H313: P&L | I313: Equity | J313: Retained earnings (Current Year) | K313: Direct Business Lines SG&A | L313: Others | M313: Others | N313: Finanzas | O313: SG&A | P313: OPEX | Q313: Combinado | R313: 0 | S313: 0 | T313: 0 | U313: 0 | V313: 0 | W313: 0 | X313: 0 | Y313: 0 | Z313: 0 | AA313: 0 | AB313: 0 | AC313: 0 | AD313: 0 | AE313: 0 | AF313: 0 | AG313: 0
B314: 610-01-000 | C314: [VCN] | D314: [VCN]610-01-000 | E314: [VCN] | F314: Gastos de personal | G314: Participación de los trabaj en utilidades dif | H314: P&L | I314: Equity | J314: Retained earnings (Current Year) | K314: Direct Business Lines SG&A | L314: Others | M314: Others | N314: Finanzas | O314: SG&A | P314: SG&A | Q314: Combinado | R314: 0 | S314: 0 | T314: 0 | U314: 0 | V314: 0 | W314: 0 | X314: 0 | Y314: 0 | Z314: 0 | AA314: 0 | AB314: 0 | AC314: -2972436.6 | AD314: 0 | AE314: 0 | AF314: 0 | AG314: 0
B315: 611-03-000 | C315: [VCN] | D315: [VCN]611-03-000 | E315: [VCN] | F315: Impuestos a la utilidad diferidos | G315: ISR Diferido causado | H315: P&L | I315: Equity | J315: Retained earnings (Current Year) | K315: Direct Business Lines SG&A | L315: Others | M315: Others | N315: Finanzas | O315: SG&A | P315: SG&A | Q315: Combinado | R315: 0 | S315: 0 | T315: 0 | U315: 0 | V315: 0 | W315: 0 | X315: 0 | Y315: 0 | Z315: 0 | AA315: 0 | AB315: 0 | AC315: -8025579.4 | AD315: 0 | AE315: 0 | AF315: 0 | AG315: 0
B316: 105-01-024 | C316: [VCN] | D316: [VCN]105-01-024 | E316: [VCN] | F316: Cuentas por cobrar comerciales | G316: DIDI | H316: BS | I316: Assets | J316: Other Accounts Receivable | K316: n.a. | L316: n.a. | M316: n.a. | N316: n.a. | O316: n.a. | Q316: Combinado | R316: 0 | S316: 0 | T316: 0 | U316: 0 | V316: 287144 | W316: 365556.6 | X316: 433315 | Y316: 603315 | Z316: 510511.36 | AA316: 156875.31 | AB316: 333632.21 | AC316: 702846 | AD316: 702846 | AE316: 0 | AF316: 0 | AG316: 0
B317: 400-200-100-0030 | C317: [VCN] | D317: [VCN]400-200-100-0030 | E317: [VCN] | F317: Ingresos operativos | G317: OTROS INGRESOS DIDI | H317: P&L | I317: Equity | J317: Retained earnings (Current Year) | K317: Revenue | L317: DiDi Charging Agreement PPC | M317: DiDi Charging Agreement PPC | N317: DiDi Charging Agreement PPC | O317: Revenue | P317: Revenue | Q317: Combinado | R317: 0 | S317: 0 | T317: 0 | U317: 0 | V317: -247537.93 | W317: -501976.12 | X317: -823842.94 | Y317: -1101604.8 | Z317: -785891 | AA317: -942766.31 | AB317: -1119523.2 | AC317: -1488737 | AD317: -271072.41 | AE317: -436400.86 | AF317: -714443.68 | AG317: -1102580.4
B318: 400-200-100-0033 | C318: [VCN] | D318: [VCN]400-200-100-0033 | E318: [VCN] | F318: Ingresos operativos | G318: INGRESOS WATTS DRIVERS LTO | H318: P&L | I318: Equity | J318: Retained earnings (Current Year) | K318: Revenue | L318: LTO Additional Consumption | M318: LTO Additional Consumption | N318: LTO Additional Consumption | O318: Revenue | P318: Revenue | Q318: Combinado | R318: 0 | S318: 0 | T318: 0 | U318: -736413 | V318: -1899494 | W318: -3166186.5 | X318: -4439364.3 | Y318: -5453046 | Z318: -7288670.5 | AA318: -8805677.4 | AB318: -10026352 | AC318: -11586178 | AD318: -691727.81 | AE318: -1658081.1 | AF318: -3774321.9 | AG318: -5779337.4
B319: 602-46-010 | C319: [VCN] | D319: [VCN]602-46-010 | E319: [VCN] | F319: Gastos generales | G319: Estacionamientos Boyen | H319: P&L | I319: Equity | J319: Retained earnings (Current Year) | K319: OPEX | L319: Rent Petrarca | M319: Rent Petrarca | N319: Charging Infra | O319: OPEX | P319: SG&A | Q319: Combinado | R319: 0 | S319: 0 | T319: 0 | U319: 0 | V319: 0 | W319: 0 | X319: 0 | Y319: 0 | Z319: 0 | AA319: 0 | AB319: 0 | AC319: 0 | AD319: 0 | AE319: 0 | AF319: 0 | AG319: 0
...

Sheet Managerial Consolidated
B1: VEMO VCN 2025 Financials | C1: Allocation | Q1: Check
A2: =SUM(A3:A1048576) -> 0 | B2: Managerial Consolidated | C2: =+Scenarios!$F$15 -> BP | Q2: =A2 -> 0
AY4: 2025 YTD | AZ4: 2026 YTD | BB4: 2025 FY (MXN $) | BC4: 2026 FY (MXN $)
Q6: 45658 | R6: 45689 | S6: 45717 | T6: 45748 | U6: 45778 | V6: 45809 | W6: 45839 | X6: 45870 | Y6: 45901 | Z6: 45931 | AA6: 45962 | AB6: 45992 | AC6: 46023 | AD6: 46054 | AE6: 46082 | AF6: 46113 | AG6: 46143 | AH6: 46174 | AI6: 46204 | AJ6: 46235 | AK6: 46266 | AL6: 46296 | AM6: 46327 | AN6: 46357 | AP6: 45658 | AQ6: 45748 | AR6: =+AQ7+1 -> 45839 | AS6: =+AR7+1 -> 45931 | AT6: 46023 | AU6: 46113 | AV6: =+AU7+1 -> 46204 | AW6: =+AV7+1 -> 46296 | AY6: 45658 | AZ6: 46023 | BB6: 45658 | BC6: 46023
B7: Month End | Q7: 45688 | R7: 45716 | S7: 45747 | T7: 45777 | U7: 45808 | V7: 45838 | W7: 45869 | X7: 45900 | Y7: 45930 | Z7: 45961 | AA7: 45991 | AB7: 46022 | AC7: 46053 | AD7: 46081 | AE7: 46112 | AF7: 46142 | AG7: 46173 | AH7: 46203 | AI7: 46234 | AJ7: 46265 | AK7: 46295 | AL7: 46326 | AM7: 46356 | AN7: 46387 | AP7: 45747 | AQ7: 45838 | AR7: 45930 | AS7: 46022 | AT7: 46112 | AU7: 46203 | AV7: 46295 | AW7: 46387 | AY7: 46022 | AZ7: 46387 | BB7: 46022 | BC7: 46387
B8: Year | Q8: 2025 | R8: 2025 | S8: 2025 | T8: 2025 | U8: 2025 | V8: 2025 | W8: 2025 | X8: 2025 | Y8: 2025 | Z8: 2025 | AA8: 2025 | AB8: 2025 | AC8: 2026 | AD8: 2026 | AE8: 2026 | AF8: 2026 | AG8: 2026 | AH8: 2026 | AI8: 2026 | AJ8: 2026 | AK8: 2026 | AL8: 2026 | AM8: 2026 | AN8: 2026 | AP8: 2025 | AQ8: 2025 | AR8: 2025 | AS8: 2025 | AT8: 2026 | AU8: 2026 | AV8: 2026 | AW8: 2026 | AY8: 2025 | AZ8: 2026 | BB8: 2025 | BC8: 2026
B9: Quarter | Q9: Q1 | R9: Q1 | S9: Q1 | T9: Q2 | U9: Q2 | V9: Q2 | W9: Q3 | X9: Q3 | Y9: Q3 | Z9: Q4 | AA9: Q4 | AB9: Q4 | AC9: Q1 | AD9: Q1 | AE9: Q1 | AF9: Q2 | AG9: Q2 | AH9: Q2 | AI9: Q3 | AJ9: Q3 | AK9: Q3 | AL9: Q4 | AM9: Q4 | AN9: Q4 | AP9: Q1 | AQ9: Q2 | AR9: Q3 | AS9: Q4 | AT9: Q1 | AU9: Q2 | AV9: Q3 | AW9: Q4 | AY9: Q4 | AZ9: Q4 | BB9: Q4 | BC9: Q4
Q10: Actuals | R10: Actuals | S10: Actuals | T10: Actuals | AC10: Actuals | AD10: Actuals | AE10: Actuals | AF10: Actuals | AY10: Actuals | AZ10: Actuals | BB10: Actuals | BC10: Actuals
B12: [VCN]
B14: P&L
B15: Revenue | Q15: =+SUMIFS('Data BASE'!R$491:R$4835,'Data BASE'!$O$491:$O$4835,'Managerial Consolidated'!$B15,'Data BASE'!$E$491:$E$4835,'Managerial Consolidated'!$B$12) -> 8790220.5 | R15: =+SUMIFS('Data BASE'!S$491:S$4835,'Data BASE'!$O$491:$O$4835,'Managerial Consolidated'!$B15,'Data BASE'!$E$491:$E$4835,'Managerial Consolidated'!$B$12) -> 8433174.4 | S15: =+SUMIFS('Data BASE'!T$491:T$4835,'Data BASE'!$O$491:$O$4835,'Managerial Consolidated'!$B15,'Data BASE'!$E$491:$E$4835,'Managerial Consolidated'!$B$12) -> 8959087.7 | T15: =+SUMIFS('Data BASE'!U$491:U$4835,'Data BASE'!$O$491:$O$4835,'Managerial Consolidated'!$B15,'Data BASE'!$E$491:$E$4835,'Managerial Consolidated'!$B$12) -> 10918876 | U15: =+SUMIFS('Data BASE'!V$491:V$4835,'Data BASE'!$O$491:$O$4835,'Managerial Consolidated'!$B15,'Data BASE'!$E$491:$E$4835,'Managerial Consolidated'!$B$12) -> 12639204 | V15: =+SUMIFS('Data BASE'!W$491:W$6729,'Data BASE'!$O$491:$O$6729,'Managerial Consolidated'!$B15,'Data BASE'!$E$491:$E$6729,'Managerial Consolidated'!$B$12) -> 12607588 | W15: =+SUMIFS('Data BASE'!X$491:X$6729,'Data BASE'!$O$491:$O$6729,'Managerial Consolidated'!$B15,'Data BASE'!$E$491:$E$6729,'Managerial Consolidated'!$B$12) -> 13082308 | X15: =+SUMIFS('Data BASE'!Y$491:Y$6729,'Data BASE'!$O$491:$O$6729,'Managerial Consolidated'!$B15,'Data BASE'!$E$491:$E$6729,'Managerial Consolidated'!$B$12) -> 13826520 | Y15: =+SUMIFS('Data BASE'!Z$491:Z$6729,'Data BASE'!$O$491:$O$6729,'Managerial Consolidated'!$B15,'Data BASE'!$E$491:$E$6729,'Managerial Consolidated'!$B$12) -> 19625870 | Z15: =+SUMIFS('Data BASE'!AA$491:AA$6729,'Data BASE'!$O$491:$O$6729,'Managerial Consolidated'!$B15,'Data BASE'!$E$491:$E$6729,'Managerial Consolidated'!$B$12) -> 15195866 | AA15: =+SUMIFS('Data BASE'!AB$491:AB$6729,'Data BASE'!$O$491:$O$6729,'Managerial Consolidated'!$B15,'Data BASE'!$E$491:$E$6729,'Managerial Consolidated'!$B$12) -> 14683864 | AB15: =+SUMIFS('Data BASE'!AC$491:AC$6729,'Data BASE'!$O$491:$O$6729,'Managerial Consolidated'!$B15,'Data BASE'!$E$491:$E$6729,'Managerial Consolidated'!$B$12) -> 16460862 | AC15: =+SUMIFS('Data BASE'!AD$491:AD$6729,'Data BASE'!$O$491:$O$6729,'Managerial Consolidated'!$B15,'Data BASE'!$E$491:$E$6729,'Managerial Consolidated'!$B$12) -> 16611360 | ... AN15: =+SUMIFS('Data BASE'!AO$491:AO$6729,'Data BASE'!$O$491:$O$6729,'Managerial Consolidated'!$B15,'Data BASE'!$E$491:$E$6729,'Managerial Consolidated'!$B$12) -> 0 | AP15: =+SUMIFS($Q15:$AO15,$Q$9:$AO$9,AP$9,$Q$8:$AO$8,AP$8) -> 26182483 | AQ15: =+SUMIFS($Q15:$AO15,$Q$9:$AO$9,AQ$9,$Q$8:$AO$8,AQ$8) -> 36165668 | AR15: =+SUMIFS($Q15:$AO15,$Q$9:$AO$9,AR$9,$Q$8:$AO$8,AR$8) -> 46534698 | AS15: =+SUMIFS($Q15:$AO15,$Q$9:$AO$9,AS$9,$Q$8:$AO$8,AS$8) -> 46340592 | AT15: =+SUMIFS($Q15:$AO15,$Q$9:$AO$9,AT$9,$Q$8:$AO$8,AT$8) -> 52058549 | AU15: =+SUMIFS($Q15:$AO15,$Q$9:$AO$9,AU$9,$Q$8:$AO$8,AU$8) -> 19311160 | AV15: =+SUMIFS($Q15:$AO15,$Q$9:$AO$9,AV$9,$Q$8:$AO$8,AV$8) -> 0 | AW15: =+SUMIFS($Q15:$AO15,$Q$9:$AO$9,AW$9,$Q$8:$AO$8,AW$8) -> 0 | AY15: =+SUMIFS(Q15:AN15,$Q$8:$AN$8,$AY$8) -> 1.5522344e+08 | AZ15: =+SUMIFS(R15:AO15,$R$8:$AO$8,$AZ$8) -> 71369709 | BB15: =SUMIFS($Q15:$AN15,$Q$8:$AN$8,BB$8) -> 1.5522344e+08 | BC15: =SUMIFS($Q15:$AN15,$Q$8:$AN$8,BC$8) -> 71369709
B16: OPEX | Q16: =-SUMIFS('Data BASE'!R$491:R$4835,'Data BASE'!$O$491:$O$4835,'Managerial Consolidated'!$B16,'Data BASE'!$E$491:$E$4835,'Managerial Consolidated'!$B$12) -> -6804038.6 | R16: =-SUMIFS('Data BASE'!S$491:S$4835,'Data BASE'!$O$491:$O$4835,'Managerial Consolidated'!$B16,'Data BASE'!$E$491:$E$4835,'Managerial Consolidated'!$B$12) -> -7474231.7 | S16: =-SUMIFS('Data BASE'!T$491:T$4835,'Data BASE'!$O$491:$O$4835,'Managerial Consolidated'!$B16,'Data BASE'!$E$491:$E$4835,'Managerial Consolidated'!$B$12) -> -7278375.2 | T16: =-SUMIFS('Data BASE'!U$491:U$4835,'Data BASE'!$O$491:$O$4835,'Managerial Consolidated'!$B16,'Data BASE'!$E$491:$E$4835,'Managerial Consolidated'!$B$12) -> -8425618.6 | U16: =-SUMIFS('Data BASE'!V$491:V$4835,'Data BASE'!$O$491:$O$4835,'Managerial Consolidated'!$B16,'Data BASE'!$E$491:$E$4835,'Managerial Consolidated'!$B$12) -> -6142528.8 | V16: =-SUMIFS('Data BASE'!W$491:W$6729,'Data BASE'!$O$491:$O$6729,'Managerial Consolidated'!$B16,'Data BASE'!$E$491:$E$6729,'Managerial Consolidated'!$B$12) -> -8343729.6 | W16: =-SUMIFS('Data BASE'!X$491:X$6729,'Data BASE'!$O$491:$O$6729,'Managerial Consolidated'!$B16,'Data BASE'!$E$491:$E$6729,'Managerial Consolidated'!$B$12) -> -8033871.5 | X16: =-SUMIFS('Data BASE'!Y$491:Y$6729,'Data BASE'!$O$491:$O$6729,'Managerial Consolidated'!$B16,'Data BASE'!$E$491:$E$6729,'Managerial Consolidated'!$B$12) -> -7160858.5 | Y16: =-SUMIFS('Data BASE'!Z$491:Z$6729,'Data BASE'!$O$491:$O$6729,'Managerial Consolidated'!$B16,'Data BASE'!$E$491:$E$6729,'Managerial Consolidated'!$B$12) -> -10039265 | Z16: =-SUMIFS('Data BASE'!AA$491:AA$6729,'Data BASE'!$O$491:$O$6729,'Managerial Consolidated'!$B16,'Data BASE'!$E$491:$E$6729,'Managerial Consolidated'!$B$12) -> -9136119.1 | AA16: =-SUMIFS('Data BASE'!AB$491:AB$6729,'Data BASE'!$O$491:$O$6729,'Managerial Consolidated'!$B16,'Data BASE'!$E$491:$E$6729,'Managerial Consolidated'!$B$12) -> -10448619 | AB16: =-SUMIFS('Data BASE'!AC$491:AC$6729,'Data BASE'!$O$491:$O$6729,'Managerial Consolidated'!$B16,'Data BASE'!$E$491:$E$6729,'Managerial Consolidated'!$B$12) -> -16983833 | AC16: =-SUMIFS('Data BASE'!AD$491:AD$6729,'Data BASE'!$O$491:$O$6729,'Managerial Consolidated'!$B16,'Data BASE'!$E$491:$E$6729,'Managerial Consolidated'!$B$12) -> -10815509 | ... AN16: =-SUMIFS('Data BASE'!AO$491:AO$6729,'Data BASE'!$O$491:$O$6729,'Managerial Consolidated'!$B16,'Data BASE'!$E$491:$E$6729,'Managerial Consolidated'!$B$12) -> 0 | AP16: =+SUMIFS($Q16:$AO16,$Q$9:$AO$9,AP$9,$Q$8:$AO$8,AP$8) -> -21556646 | AQ16: =+SUMIFS($Q16:$AO16,$Q$9:$AO$9,AQ$9,$Q$8:$AO$8,AQ$8) -> -22911877 | AR16: =+SUMIFS($Q16:$AO16,$Q$9:$AO$9,AR$9,$Q$8:$AO$8,AR$8) -> -25233995 | AS16: =+SUMIFS($Q16:$AO16,$Q$9:$AO$9,AS$9,$Q$8:$AO$8,AS$8) -> -36568571 | AT16: =+SUMIFS($Q16:$AO16,$Q$9:$AO$9,AT$9,$Q$8:$AO$8,AT$8) -> -38637461 | AU16: =+SUMIFS($Q16:$AO16,$Q$9:$AO$9,AU$9,$Q$8:$AO$8,AU$8) -> -13085247 | AV16: =+SUMIFS($Q16:$AO16,$Q$9:$AO$9,AV$9,$Q$8:$AO$8,AV$8) -> 0 | AW16: =+SUMIFS($Q16:$AO16,$Q$9:$AO$9,AW$9,$Q$8:$AO$8,AW$8) -> 0 | AY16: =+SUMIFS(Q16:AN16,$Q$8:$AN$8,$AY$8) -> -1.0627109e+08 | AZ16: =+SUMIFS(R16:AO16,$R$8:$AO$8,$AZ$8) -> -51722709 | BB16: =SUMIFS($Q16:$AB16,$Q$8:$AB$8,BB$8) -> -1.0627109e+08 | BC16: =SUMIFS($Q16:$AN16,$Q$8:$AN$8,BC$8) -> -51722709
B17: Gross Profit | Q17: =+Q15+Q16 -> 1986181.9 | R17: =+R15+R16 -> 958942.72 | S17: =+S15+S16 -> 1680712.4 | T17: =+T15+T16 -> 2493257.6 | U17: =+U15+U16 -> 6496675.1 | V17: =+V15+V16 -> 4263858.1 | W17: =+W15+W16 -> 5048436.6 | X17: =+X15+X16 -> 6665661.7 | ... AN17: =+AN15+AN16 -> 0 | AP17: =+AP15+AP16 -> 4625837 | AQ17: =+AQ15+AQ16 -> 13253791 | AR17: =+AR15+AR16 -> 21300703 | AS17: =+AS15+AS16 -> 9772020.8 | AT17: =+AT15+AT16 -> 13421088 | AU17: =+AU15+AU16 -> 6225912.4 | AV17: =+AV15+AV16 -> 0 | AW17: =+AW15+AW16 -> 0 | AY17: =+SUMIFS(Q17:AN17,$Q$8:$AN$8,$AY$8) -> 48952352 | AZ17: =+SUMIFS(R17:AO17,$R$8:$AO$8,$AZ$8) -> 19647000 | BB17: =+BB15+BB16 -> 48952352 | BC17: =+BC15+BC16 -> 19647000
B18: SG&A | Q18: =-SUMIFS('Data BASE'!R$491:R$4835,'Data BASE'!$O$491:$O$4835,'Managerial Consolidated'!$B18,'Data BASE'!$E$491:$E$4835,'Managerial Consolidated'!$B$12) -> -5279058.7 | R18: =-SUMIFS('Data BASE'!S$491:S$4835,'Data BASE'!$O$491:$O$4835,'Managerial Consolidated'!$B18,'Data BASE'!$E$491:$E$4835,'Managerial Consolidated'!$B$12) -> -5640888.9 | S18: =-SUMIFS('Data BASE'!T$491:T$4835,'Data BASE'!$O$491:$O$4835,'Managerial Consolidated'!$B18,'Data BASE'!$E$491:$E$4835,'Managerial Consolidated'!$B$12) -> -6616945.4 | T18: =-SUMIFS('Data BASE'!U$491:U$4835,'Data BASE'!$O$491:$O$4835,'Managerial Consolidated'!$B18,'Data BASE'!$E$491:$E$4835,'Managerial Consolidated'!$B$12) -> -6100327.7 | U18: =-SUMIFS('Data BASE'!V$491:V$4835,'Data BASE'!$O$491:$O$4835,'Managerial Consolidated'!$B18,'Data BASE'!$E$491:$E$4835,'Managerial Consolidated'!$B$12) -> -7956129.4 | V18: =-SUMIFS('Data BASE'!W$491:W$6729,'Data BASE'!$O$491:$O$6729,'Managerial Consolidated'!$B18,'Data BASE'!$E$491:$E$6729,'Managerial Consolidated'!$B$12) -> -7425617.7 | W18: =-SUMIFS('Data BASE'!X$491:X$6729,'Data BASE'!$O$491:$O$6729,'Managerial Consolidated'!$B18,'Data BASE'!$E$491:$E$6729,'Managerial Consolidated'!$B$12) -> -8993803 | X18: =-SUMIFS('Data BASE'!Y$491:Y$6729,'Data BASE'!$O$491:$O$6729,'Managerial Consolidated'!$B18,'Data BASE'!$E$491:$E$6729,'Managerial Consolidated'!$B$12) -> -9180419.4 | Y18: =-SUMIFS('Data BASE'!Z$491:Z$6729,'Data BASE'!$O$491:$O$6729,'Managerial Consolidated'!$B18,'Data BASE'!$E$491:$E$6729,'Managerial Consolidated'!$B$12) -> -8666059.3 | Z18: =-SUMIFS('Data BASE'!AA$491:AA$6729,'Data BASE'!$O$491:$O$6729,'Managerial Consolidated'!$B18,'Data BASE'!$E$491:$E$6729,'Managerial Consolidated'!$B$12) -> -11109351 | AA18: =-SUMIFS('Data BASE'!AB$491:AB$6729,'Data BASE'!$O$491:$O$6729,'Managerial Consolidated'!$B18,'Data BASE'!$E$491:$E$6729,'Managerial Consolidated'!$B$12) -> -10019278 | AB18: =-SUMIFS('Data BASE'!AC$491:AC$6729,'Data BASE'!$O$491:$O$6729,'Managerial Consolidated'!$B18,'Data BASE'!$E$491:$E$6729,'Managerial Consolidated'!$B$12) -> 7996059.3 | AC18: =-SUMIFS('Data BASE'!AD$491:AD$6729,'Data BASE'!$O$491:$O$6729,'Managerial Consolidated'!$B18,'Data BASE'!$E$491:$E$6729,'Managerial Consolidated'!$B$12) -> -10194612 | ... AN18: =-SUMIFS('Data BASE'!AO$491:AO$6729,'Data BASE'!$O$491:$O$6729,'Managerial Consolidated'!$B18,'Data BASE'!$E$491:$E$6729,'Managerial Consolidated'!$B$12) -> 0 | AP18: =+SUMIFS($Q18:$AO18,$Q$9:$AO$9,AP$9,$Q$8:$AO$8,AP$8) -> -17536893 | AQ18: =+SUMIFS($Q18:$AO18,$Q$9:$AO$9,AQ$9,$Q$8:$AO$8,AQ$8) -> -21482075 | AR18: =+SUMIFS($Q18:$AO18,$Q$9:$AO$9,AR$9,$Q$8:$AO$8,AR$8) -> -26840282 | AS18: =+SUMIFS($Q18:$AO18,$Q$9:$AO$9,AS$9,$Q$8:$AO$8,AS$8) -> -13132570 | AT18: =+SUMIFS($Q18:$AO18,$Q$9:$AO$9,AT$9,$Q$8:$AO$8,AT$8) -> -31006229 | AU18: =+SUMIFS($Q18:$AO18,$Q$9:$AO$9,AU$9,$Q$8:$AO$8,AU$8) -> -11903987 | AV18: =+SUMIFS($Q18:$AO18,$Q$9:$AO$9,AV$9,$Q$8:$AO$8,AV$8) -> 0 | AW18: =+SUMIFS($Q18:$AO18,$Q$9:$AO$9,AW$9,$Q$8:$AO$8,AW$8) -> 0 | AY18: =+SUMIFS(Q18:AN18,$Q$8:$AN$8,$AY$8) -> -78991819 | AZ18: =+SUMIFS(R18:AO18,$R$8:$AO$8,$AZ$8) -> -42910216 | BB18: =SUMIFS($Q18:$AB18,$Q$8:$AB$8,BB$8) -> -78991819 | BC18: =SUMIFS($Q18:$AN18,$Q$8:$AN$8,BC$8) -> -42910216
B19: FX | Q19: =-SUMIFS('Data BASE'!R$491:R$4835,'Data BASE'!$O$491:$O$4835,'Managerial Consolidated'!$B19,'Data BASE'!$E$491:$E$4835,'Managerial Consolidated'!$B$12) -> -324.55 | R19: =-SUMIFS('Data BASE'!S$491:S$4835,'Data BASE'!$O$491:$O$4835,'Managerial Consolidated'!$B19,'Data BASE'!$E$491:$E$4835,'Managerial Consolidated'!$B$12) -> -3714.69 | S19: =-SUMIFS('Data BASE'!T$491:T$4835,'Data BASE'!$O$491:$O$4835,'Managerial Consolidated'!$B19,'Data BASE'!$E$491:$E$4835,'Managerial Consolidated'!$B$12) -> 334893.49 | T19: =-SUMIFS('Data BASE'!U$491:U$4835,'Data BASE'!$O$491:$O$4835,'Managerial Consolidated'!$B19,'Data BASE'!$E$491:$E$4835,'Managerial Consolidated'!$B$12) -> -278953.64 | U19: =-SUMIFS('Data BASE'!V$491:V$4835,'Data BASE'!$O$491:$O$4835,'Managerial Consolidated'!$B19,'Data BASE'!$E$491:$E$4835,'Managerial Consolidated'!$B$12) -> -1025887.1 | V19: =-SUMIFS('Data BASE'!W$491:W$6729,'Data BASE'!$O$491:$O$6729,'Managerial Consolidated'!$B19,'Data BASE'!$E$491:$E$6729,'Managerial Consolidated'!$B$12) -> -600742.23 | W19: =-SUMIFS('Data BASE'!X$491:X$6729,'Data BASE'!$O$491:$O$6729,'Managerial Consolidated'!$B19,'Data BASE'!$E$491:$E$6729,'Managerial Consolidated'!$B$12) -> -93418.53 | X19: =-SUMIFS('Data BASE'!Y$491:Y$6729,'Data BASE'!$O$491:$O$6729,'Managerial Consolidated'!$B19,'Data BASE'!$E$491:$E$6729,'Managerial Consolidated'!$B$12) -> -57849.27 | Y19: =-SUMIFS('Data BASE'!Z$491:Z$6729,'Data BASE'!$O$491:$O$6729,'Managerial Consolidated'!$B19,'Data BASE'!$E$491:$E$6729,'Managerial Consolidated'!$B$12) -> -240833.11 | Z19: =-SUMIFS('Data BASE'!AA$491:AA$6729,'Data BASE'!$O$491:$O$6729,'Managerial Consolidated'!$B19,'Data BASE'!$E$491:$E$6729,'Managerial Consolidated'!$B$12) -> -41831.81 | AA19: =-SUMIFS('Data BASE'!AB$491:AB$6729,'Data BASE'!$O$491:$O$6729,'Managerial Consolidated'!$B19,'Data BASE'!$E$491:$E$6729,'Managerial Consolidated'!$B$12) -> -27117.46 | AB19: =-SUMIFS('Data BASE'!AC$491:AC$6729,'Data BASE'!$O$491:$O$6729,'Managerial Consolidated'!$B19,'Data BASE'!$E$491:$E$6729,'Managerial Consolidated'!$B$12) -> 40269.14 | AC19: =-SUMIFS('Data BASE'!AD$491:AD$6729,'Data BASE'!$O$491:$O$6729,'Managerial Consolidated'!$B19,'Data BASE'!$E$491:$E$6729,'Managerial Consolidated'!$B$12) -> -61032.41 | ... AN19: =-SUMIFS('Data BASE'!AO$491:AO$6729,'Data BASE'!$O$491:$O$6729,'Managerial Consolidated'!$B19,'Data BASE'!$E$491:$E$6729,'Managerial Consolidated'!$B$12) -> 0 | AP19: =+SUMIFS($Q19:$AO19,$Q$9:$AO$9,AP$9,$Q$8:$AO$8,AP$8) -> 330854.25 | AQ19: =+SUMIFS($Q19:$AO19,$Q$9:$AO$9,AQ$9,$Q$8:$AO$8,AQ$8) -> -1905582.9 | AR19: =+SUMIFS($Q19:$AO19,$Q$9:$AO$9,AR$9,$Q$8:$AO$8,AR$8) -> -392100.91 | AS19: =+SUMIFS($Q19:$AO19,$Q$9:$AO$9,AS$9,$Q$8:$AO$8,AS$8) -> -28680.13 | AT19: =+SUMIFS($Q19:$AO19,$Q$9:$AO$9,AT$9,$Q$8:$AO$8,AT$8) -> -194257.19 | AU19: =+SUMIFS($Q19:$AO19,$Q$9:$AO$9,AU$9,$Q$8:$AO$8,AU$8) -> 4648.05 | AV19: =+SUMIFS($Q19:$AO19,$Q$9:$AO$9,AV$9,$Q$8:$AO$8,AV$8) -> 0 | AW19: =+SUMIFS($Q19:$AO19,$Q$9:$AO$9,AW$9,$Q$8:$AO$8,AW$8) -> 0 | AY19: =+SUMIFS(Q19:AN19,$Q$8:$AN$8,$AY$8) -> -1995509.7 | AZ19: =+SUMIFS(R19:AO19,$R$8:$AO$8,$AZ$8) -> -189609.14 | BB19: =SUMIFS($Q19:$AB19,$Q$8:$AB$8,BB$8) -> -1995509.7 | BC19: =SUMIFS($Q19:$AN19,$Q$8:$AN$8,BC$8) -> -189609.14
B20: EBITDA | Q20: =+Q17+Q18+Q19 -> -3293201.3 | R20: =+R17+R18+R19 -> -4685660.8 | S20: =+S17+S18+S19 -> -4601339.5 | T20: =+T17+T18+T19 -> -3886023.7 | U20: =+U17+U18+U19 -> -2485341.3 | V20: =+V17+V18+V19 -> -3762501.8 | W20: =+W17+W18+W19 -> -4038785 | X20: =+X17+X18+X19 -> -2572606.9 | ... AN20: =+AN17+AN18+AN19 -> 0 | AP20: =+AP17+AP18+AP19 -> -12580202 | AQ20: =+AQ17+AQ18+AQ19 -> -10133867 | AR20: =+AR17+AR18+AR19 -> -5931679.4 | AS20: =+AS17+AS18+AS19 -> -3389229.3 | AT20: =+AT17+AT18+AT19 -> -17779399 | AU20: =+AU17+AU18+AU19 -> -5673426.2 | AV20: =+AV17+AV18+AV19 -> 0 | AW20: =+AW17+AW18+AW19 -> 0 | AY20: =+SUMIFS(Q20:AN20,$Q$8:$AN$8,$AY$8) -> -32034977 | AZ20: =+SUMIFS(R20:AO20,$R$8:$AO$8,$AZ$8) -> -23452825 | BB20: =+BB17+BB18+BB19 -> -32034977 | BC20: =+BC17+BC18+BC19 -> -23452825
B21: D&A | Q21: =-SUMIFS('Data BASE'!R$491:R$4835,'Data BASE'!$O$491:$O$4835,'Managerial Consolidated'!$B21,'Data BASE'!$E$491:$E$4835,'Managerial Consolidated'!$B$12) -> -1714955.6 | R21: =-SUMIFS('Data BASE'!S$491:S$4835,'Data BASE'!$O$491:$O$4835,'Managerial Consolidated'!$B21,'Data BASE'!$E$491:$E$4835,'Managerial Consolidated'!$B$12) -> -1840310.3 | S21: =-SUMIFS('Data BASE'!T$491:T$4835,'Data BASE'!$O$491:$O$4835,'Managerial Consolidated'!$B21,'Data BASE'!$E$491:$E$4835,'Managerial Consolidated'!$B$12) -> -1830631.2 | T21: =-SUMIFS('Data BASE'!U$491:U$4835,'Data BASE'!$O$491:$O$4835,'Managerial Consolidated'!$B21,'Data BASE'!$E$491:$E$4835,'Managerial Consolidated'!$B$12) -> -2474407.3 | U21: =-SUMIFS('Data BASE'!V$491:V$4835,'Data BASE'!$O$491:$O$4835,'Managerial Consolidated'!$B21,'Data BASE'!$E$491:$E$4835,'Managerial Consolidated'!$B$12) -> -2424952.6 | V21: =-SUMIFS('Data BASE'!W$491:W$6729,'Data BASE'!$O$491:$O$6729,'Managerial Consolidated'!$B21,'Data BASE'!$E$491:$E$6729,'Managerial Consolidated'!$B$12) -> -2384325.8 | W21: =-SUMIFS('Data BASE'!X$491:X$6729,'Data BASE'!$O$491:$O$6729,'Managerial Consolidated'!$B21,'Data BASE'!$E$491:$E$6729,'Managerial Consolidated'!$B$12) -> -2890391.3 | X21: =-SUMIFS('Data BASE'!Y$491:Y$6729,'Data BASE'!$O$491:$O$6729,'Managerial Consolidated'!$B21,'Data BASE'!$E$491:$E$6729,'Managerial Consolidated'!$B$12) -> -2545876.5 | Y21: =-SUMIFS('Data BASE'!Z$491:Z$6729,'Data BASE'!$O$491:$O$6729,'Managerial Consolidated'!$B21,'Data BASE'!$E$491:$E$6729,'Managerial Consolidated'!$B$12) -> -2736711.9 | Z21: =-SUMIFS('Data BASE'!AA$491:AA$6729,'Data BASE'!$O$491:$O$6729,'Managerial Consolidated'!$B21,'Data BASE'!$E$491:$E$6729,'Managerial Consolidated'!$B$12) -> -2636109.1 | AA21: =-SUMIFS('Data BASE'!AB$491:AB$6729,'Data BASE'!$O$491:$O$6729,'Managerial Consolidated'!$B21,'Data BASE'!$E$491:$E$6729,'Managerial Consolidated'!$B$12) -> -3049047.2 | AB21: =-SUMIFS('Data BASE'!AC$491:AC$6729,'Data BASE'!$O$491:$O$6729,'Managerial Consolidated'!$B21,'Data BASE'!$E$491:$E$6729,'Managerial Consolidated'!$B$12) -> -9971241 | AC21: =-SUMIFS('Data BASE'!AD$491:AD$6729,'Data BASE'!$O$491:$O$6729,'Managerial Consolidated'!$B21,'Data BASE'!$E$491:$E$6729,'Managerial Consolidated'!$B$12) -> -5110921.4 | ... AN21: =-SUMIFS('Data BASE'!AO$491:AO$6729,'Data BASE'!$O$491:$O$6729,'Managerial Consolidated'!$B21,'Data BASE'!$E$491:$E$6729,'Managerial Consolidated'!$B$12) -> 0 | AP21: =+SUMIFS($Q21:$AO21,$Q$9:$AO$9,AP$9,$Q$8:$AO$8,AP$8) -> -5385897.1 | AQ21: =+SUMIFS($Q21:$AO21,$Q$9:$AO$9,AQ$9,$Q$8:$AO$8,AQ$8) -> -7283685.7 | AR21: =+SUMIFS($Q21:$AO21,$Q$9:$AO$9,AR$9,$Q$8:$AO$8,AR$8) -> -8172979.7 | AS21: =+SUMIFS($Q21:$AO21,$Q$9:$AO$9,AS$9,$Q$8:$AO$8,AS$8) -> -15656397 | AT21: =+SUMIFS($Q21:$AO21,$Q$9:$AO$9,AT$9,$Q$8:$AO$8,AT$8) -> -15739642 | AU21: =+SUMIFS($Q21:$AO21,$Q$9:$AO$9,AU$9,$Q$8:$AO$8,AU$8) -> -5548251.7 | AV21: =+SUMIFS($Q21:$AO21,$Q$9:$AO$9,AV$9,$Q$8:$AO$8,AV$8) -> 0 | AW21: =+SUMIFS($Q21:$AO21,$Q$9:$AO$9,AW$9,$Q$8:$AO$8,AW$8) -> 0 | AY21: =+SUMIFS(Q21:AN21,$Q$8:$AN$8,$AY$8) -> -36498960 | AZ21: =+SUMIFS(R21:AO21,$R$8:$AO$8,$AZ$8) -> -21287893 | BB21: =SUMIFS($Q21:$AB21,$Q$8:$AB$8,BB$8) -> -36498960 | BC21: =SUMIFS($Q21:$AN21,$Q$8:$AN$8,BC$8) -> -21287893
B22: EBIT | Q22: =+Q20+Q21 -> -5008156.9 | R22: =+R20+R21 -> -6525971.1 | S22: =+S20+S21 -> -6431970.7 | T22: =+T20+T21 -> -6360431 | U22: =+U20+U21 -> -4910294 | V22: =+V20+V21 -> -6146827.6 | W22: =+W20+W21 -> -6929176.3 | X22: =+X20+X21 -> -5118483.4 | ... AN22: =+AN20+AN21 -> 0 | AP22: =+AP20+AP21 -> -17966099 | AQ22: =+AQ20+AQ21 -> -17417553 | AR22: =+AR20+AR21 -> -14104659 | AS22: =+AS20+AS21 -> -19045627 | AT22: =+AT20+AT21 -> -33519041 | AU22: =+AU20+AU21 -> -11221678 | AV22: =+AV20+AV21 -> 0 | AW22: =+AW20+AW21 -> 0 | AY22: =+SUMIFS(Q22:AN22,$Q$8:$AN$8,$AY$8) -> -68533937 | AZ22: =+SUMIFS(R22:AO22,$R$8:$AO$8,$AZ$8) -> -44740719 | BB22: =+BB20+BB21 -> -68533937 | BC22: =+BC20+BC21 -> -44740719
